<?xml version="1.0" ?>
<robot name="turbine" xmlns:xacro="http://www.ros.org/wiki/xacro">
<xacro:arg name="prefix" default="turbine"/>

<link name="$(arg prefix)/pole"> 
    <visual>
         <origin xyz="-0.2 0 -1.9" rpy="0 0 0" />
<!--          <origin xyz="0 0 -5.1" rpy="0 0 0" /> -->
      <geometry>
        <!--box size="0.102 0.109 0.106" /-->
        <mesh filename="package://marine_presenter/objects/mesh/pole.ive"  scale="1 1 1"/>
      </geometry>
    </visual> 
  </link>
  
  <joint name="turbine" type="continuous">
    <parent link="$(arg prefix)/pole"/>
    <child link="$(arg prefix)/blades"/>
    <axis xyz="0 0 1"/>
    <origin xyz="-0.5 0 0.5" rpy="0 1.5707963267948966 0" />
  </joint>  
  
  <link name="$(arg prefix)/blades">  
    <visual>
         <origin xyz="5.95 0.5 0" rpy="0 -1.5707963267948966 0" />
      <geometry>
        <mesh filename="package://marine_presenter/objects/mesh/blades.ive"  scale="1 1 1"/>
      </geometry>
    </visual> 
  </link>
</robot>
